Workbook
Name TAAL: Data!$B$4

Sheet Data
A1: Gegevens | B1: invulinstructie: gele/gouden cellen hieronder invullen of aanpassen
A2: HBO opleiding
A3: Traject
A4: Taal | B4: Nederlands
A5: Periode | B5: najaar 2024
A6: Naam Student 1 | B6: Student 1
A7: Studentnummer student 1 | B7: nummer 1
A8: Naam Student 2 | B8: Student 2 | C8: > vul in n.v.t. indien stage of single afstudeerder
A9: Studentnummer student 2 | B9: nummer 2 | C9: > laat leeg in geval van stage of single afstudeerder
A10: Bedrijfsnaam | B10: bedrijfsnaam
A11: Bedrijfsbegeleider | B11: begeleider bedrijf
A12: Titel Opdracht | B12: opdr titel
A13: Docent-begeleider | B13: docent 1
A14: 2de docent | B14: docent 2
A15: Extern gecommiteerde | B15: externe
A17: >>> Hieronder hoef je niets aan te passen! <<<
A20: JA/NEE | B20: MAJOR | C20: TRAJECT | D20: PERIODE | E20: KOPJES / HEADINGS
A21: JA | B21: Informatica (BIM) | C21: Stage | D21: najaar 2024 | E21: Bijzonderheden
A22: NEE | B22: Informatica (SO) | C22: Afstuderen | D22: voorjaar 2025 | E22: Special circumstances
D23: najaar 2025 | E23: Motivatie en toelichting
A24: OORDEEL TUSSENBEOORDELING | B24: Preliminary Evaluation | C24: TAAL | D24: voorjaar 2026 | E24: Explanation and motivation
A25: groen | B25: green | C25: Nederlands | E25: Oordeel
A26: oranje | B26: orange | C26: Engels | E26: Grade
A27: rood | B27: red | E27: Beoordelingsprognose
A28: wit | B28: white | E28: Preliminary evaluation
A29: onbekend | B29: unknown | E29: Gemaakte afspraken
E30: What to do?
A31: OORDEEL & CIJFER EINDBEOORDELING | D31: RUWE NORMERING | E31: Opgeleverde producten
A32: Uitmuntend | B32: Excellent | C32: 10 | E32: Realised Deliverables
A33: Zeer goed | B33: Very good | C33: 9 | D33: Aan alle criteria wordt voldaan en deze zijn uitgebreid uitgewerkt en onderbouwd | E33: Bijzondere omstandigheden
A34: Goed | B34: Good | C34: 8 | E34: Special circumstances
A35: NORM (Ruim voldoende) | B35: Standard (More than sufficient) | C35: 7 | D35: Aan alle criteria wordt voldaan | E35: Adviesbeoordeling Bedrijfsbegeleider
A36: Voldoende | B36: Sufficient | C36: 6 | E36: Grading Advice Company
A37: Bijna voldoende | B37: Almost sufficient | C37: 5 | D37: Aan enkele criteria wordt niet voldaan | E37: Afstudeertraject
A38: Onvoldoende | B38: Insufficient | C38: 4 | E38: The whole project
A39: Zeer onvoldoende | B39: Very unsatisfactory | C39: 3
A40: Slecht | B40: Bad | C40: 2
A41: Zeer slecht / niet beoordeelbaar | B41: Very bad / not assessable | C41: 1

Sheet Competenties
A1: Competenties | D1: Competences
A2: Competentie | B2: Beschrijving criteria | D2: Competence | E2: Description criteria
A3: Competentie 1: Planmatig werken | B3: WAT & WAAROM • Student geeft de context van de opdracht aan, waarbij probleem en/of aanleiding, doel, stakeholders en scope duidelijk worden • Student beschrijft de beoogde deliverables (producten, handelingen) van de opdracht • Student neemt hierbij (zoals stakeholders, deliverables) zowel school als bedrijf mee, in de juiste balans. HOE • Student bepaalt fasen en activiteiten bij de opdracht, verwerkt deze in een realistische planning, en bepaalt relevante risico’s en bijpassende maatregelen • Student onderbouwt de gekozen aanpak (methoden & technieken), welke past bij doel en context van de opdracht • Student werkt volgens het PvA en wijkt hier in overleg vanaf waar nodig. MATE VAN ZELFSTANDIGHEID • Student(en) komt/komen zelfstandig tot een bruikbaar (samenhangend, volledig en van voldoende kwaliteit) Plan van Aanpak. | D3: Competence 1: Working systematically | E3: WHAT & WHY • Student indicates the context of the assignment, whereby the problem and/or reason, goal, stakeholders and scope become clear • Student describes the intended deliverables (products, actions) of the assignment • Student takes (such as stakeholders, deliverables ) both school and company, in the right balance. HOW • Student determines phases and activities for the assignment, incorporates these into a realistic planning, and determines relevant risks and appropriate measures • Student substantiates the chosen approach (methods & techniques), which fits the purpose and context of the assignment • Student works according to the PvA and deviates from this in consultation where necessary. DEGREE OF INDEPENDENCE • Student(s) independently arrive at a usable (cohesive, complete and of sufficient quality) Action Plan.
A4: Competentie 2: Probleem-oplossend vermogen, leveren van beroepsprestaties | B4: EISEN • Student formuleert vooraf heldere eisen aan de deliverables, welke aansluiten bij de behoeften van de opdrachtgever/klant UITVOEREN • Student realiseert de benodigde deliverables conform die eisen en verwachtingen • Student onderbouwt de keuzes gemaakt tijdens het realiseren van die deliverables • Student borgt de kwaliteit van de deliverables door passende tests, controles, validaties OVERDRACHT • Student zorgt er middels implementatie/overdrachts-activiteiten voor dat de opdrachtgever daadwerkelijk succes kan hebben met de geleverde resultaten • Student heeft een tevreden opdrachtgever MATE VAN ZELFSTANDIGHEID • Student(en) heeft/hebben hierin zelfstandig gewerkt. | D4: Competence 2: Problem-solving ability, delivering professional performance | E4: REQUIREMENTS • Student formulates clear requirements for the deliverables in advance, which match the needs of the client/client IMPLEMENTATION • Student realizes the required deliverables in accordance with those requirements and expectations • Student substantiates the choices made during the realization of those deliverables • Student guarantees quality of the deliverables through appropriate tests, checks, validations TRANSFER • Student ensures through implementation/transfer activities that the client can actually have success with the results delivered • Student has a satisfied client DEGREE OF INDEPENDENCE • Student(s) has/have worked independently.
A5: Competentie 3: Onderzoekend vermogen | B5: ONDERZOEKEN • Student bepaalt een relevante hoofdvraag/probleemstelling • Student voert op systematische wijze onderzoek uit (denk aan: construeren logische set onderzoeksvragen, kiezen van passende onderzoeksmethoden, triangulatie, etc.) • Student verzamelt en analyseert ontbrekende informatie uit diverse bronnen KRITISCH DENKEN • Student gebruikt hierbij (wetenschappelijke) inzichten van anderen, oriënteert zich breed en is kritisch op gebruikte bronnen • Student overweegt alternatieven en onderbouwt keuzes door middel van onafhankelijke/objectieve informatie en logische redenering MATE VAN ZELFSTANDIGHEID • Student(en) heeft/hebben hierin zelfstandig gewerkt. | D5: Competence 3: Investigative ability | E5: RESEARCH • Student determines a relevant main question/problem • Student conducts research in a systematic manner (such as: constructing a logical set of research questions, choosing appropriate research methods, triangulation, etc.) • Student collects and analyzes missing information from various sources CRITICAL THINKING • Student uses (scientific) insights of others, orients himself broadly and is critical of the sources used • Student considers alternatives and substantiates choices by means of independent/objective information and logical reasoning DEGREE OF INDEPENDENCE • Student(s) has/have worked independently.
A6: Competentie 4: Samenwerken & communiceren | B6: PROACTIEVE HOUDING • Student stemt proactief af met de relevante stakeholders, waaronder in elk geval de opdrachtgever, bedrijfsbegeleider en docent-begeleider. Daaronder valt in ieder geval het op de hoogte houden van de voortgang. MONDELING • Student laat goede mondelinge communicatievaardigheden zien, in bijvoorbeeld gesprekken en presentaties SCHRIFTELIJK • Student laat goede schriftelijke communicatievaardigheden zien (goed gestructureerd, taalgebruik is verzorgd, en voldoende passend bij de doelgroep) | D6: Competency 4: Collaborate & communicate | E6: PROACTIVE ATTITUDE • The student proactively coordinates with the relevant stakeholders, including in any case the client, company supervisor and lecturer-supervisor. In any case, this includes keeping you informed of progress. ORAL • Student demonstrates good oral communication skills, for example in conversations and presentations. WRITTEN • Student demonstrates good written communication skills (well-structured, language use is correct, and appropriate to the target group)
A7: Competentie 5: Professionele houding | B7: PROFESSIONEEL WERKNEMER/OPDRACHTNEMER • Student functioneert als beginnend professional in de organisatie • Student toont eigenaarschap voor de opdracht en neemt initiatief om de opdracht succesvol te voltooien MAATSCHAPPELIJKE VERANTWOORDELIJKHEID • Student houdt bij het uitvoeren van de opdracht expliciet rekening met de impact op anderen (denk aan: de maatschappij, milieu/planeet, privacy/security, etc.). ZELFSTURING • Student heeft inzicht in eigen competenties en handelen (zelfreflectie) • Student toont eigenaarschap van de persoonlijke ontwikkeling door onderbouwde keuzes te maken • Student gaat professioneel en effectief om met (on)gevraagde feedback | D7: Competence 5: Professional attitude | E7: PROFESSIONAL EMPLOYEE/CONTRACTOR • Student functions as a starting professional in the organization • Student shows ownership of the assignment and takes initiative to successfully complete the assignment SOCIAL RESPONSIBILITY • Student explicitly takes into account the impact on others when carrying out the assignment (think of : society, environment/planet, privacy/security, etc.). SELF-MANAGEMENT • Student has insight into own competences and actions (self-reflection) • Student shows ownership of personal development by making substantiated choices • Student deals professionally and effectively with (un)solicited feedback

Sheet Feedback bedrijfsbegeleider
A1: Feedback tijdens fasegesprekken | B1: invulinstructie: vul de witte cellen in, maak waar van toepassing onderscheid tussen de studenten (gebruik ALT+Enter voor nieuwe tekstregel binnen de cel)
A2: =Data!B3 -> 0 | B2: =Data!B5 -> najaar 2024
A3: Student 1 (naam & studentnummer) | B3: =Data!B6 -> Student 1 | C3: =Data!B7 -> nummer 1
A4: Student 2 (naam & studentnummer) | B4: =Data!B8 -> Student 2 | C4: =Data!B9 -> nummer 2
A5: Titel opdracht | B5: =Data!B12 -> opdr titel
A6: Naam bedrijfsbegeleider | B6: =Data!B11 -> begeleider bedrijf
A7: Naam docent-begeleider | B7: =Data!B13 -> docent 1
A8: Naam 2de docent (voorzitter) | B8: =Data!B14 -> docent 2
A9: Naam extern gecommitteerde | B9: =Data!B15 -> externe
B10: FASE 1 | D10: FASE 2 | F10: FASE 3 | H10: =IF(TAAL="Engels", Data!$E$38,Data!$E$37) -> Afstudeertraject | K10: FASE 5/6 | M10: HERKANSING
A11: Datum (van invullen)
A12: VOORAF | B12: =IF(TAAL="Engels", Data!$E$32,Data!$E$31) -> Opgeleverde producten | D12: =IF(TAAL="Engels", Data!$E$32,Data!$E$31) -> Opgeleverde producten | F12: =IF(TAAL="Engels", Data!$E$32,Data!$E$31) -> Opgeleverde producten | H12: =IF(TAAL="Engels", Data!$E$32,Data!$E$31) -> Opgeleverde producten | K12: =IF(TAAL="Engels", Data!$E$32,Data!$E$31) -> Opgeleverde producten | M12: Voer hier de voorlopige beoordeling in ter voorbereiding op de herkansingszitting.
B14: =IF(TAAL="Engels", Data!$E$34,Data!$E$33) -> Bijzondere omstandigheden | D14: =IF(TAAL="Engels", Data!$E$34,Data!$E$33) -> Bijzondere omstandigheden | F14: =IF(TAAL="Engels", Data!$E$34,Data!$E$33) -> Bijzondere omstandigheden | H14: =IF(TAAL="Engels", Data!$E$34,Data!$E$33) -> Bijzondere omstandigheden | K14: =IF(TAAL="Engels", Data!$E$34,Data!$E$33) -> Bijzondere omstandigheden
I15: Voer hier de cijferbeoordeling in als advies voor de zitting.
A16: =IF(TAAL="Engels", Competenties!$D$3, Competenties!$A$3) -> Competentie 1: Planmatig werken | B16: =IF(TAAL="Engels", Data!$E$24,Data!$E$23) -> Motivatie en toelichting | D16: =IF(TAAL="Engels", Data!$E$24,Data!$E$23) -> Motivatie en toelichting | F16: =IF(TAAL="Engels", Data!$E$24,Data!$E$23) -> Motivatie en toelichting | H16: =IF(TAAL="Engels", Data!$E$24,Data!$E$23) -> Motivatie en toelichting | K16: =IF(TAAL="Engels", Data!$E$24,Data!$E$23) -> Motivatie en toelichting
A17: =IF(TAAL="Engels", Competenties!$E$3, Competenties!$B$3) -> WAT & WAAROM • Student geeft de context van de opdracht aan, waarbij probleem en/of aanleiding, doel, stakeholders en scope duidelijk worden • Student beschrijft de beoogde deliverables (producten, handelingen) van de opdracht • Student neemt hierbij (zoals stakeholders, deliverables) zowel school als bedrijf mee, in de juiste balans. HOE • Student bepaalt fasen en activiteiten bij de opdracht, verwerkt deze in een realistische planning, en bepaalt relevante risico’s en bijpassende maatregelen • Student onderbouwt de gekozen aanpak (methoden & technieken), welke past bij doel en context van de opdracht • Student werkt volgens het PvA en wijkt hier in overleg vanaf waar nodig. MATE VAN ZELFSTANDIGHEID • Student(en) komt/komen zelfstandig tot een bruikbaar (samenhangend, volledig en van voldoende kwaliteit) Plan van Aanpak. | B17: ...noteer hier de belangrijkste feedback voor beide studenten | D17: ...noteer hier de belangrijkste feedback voor beide studenten | F17: ...noteer hier de belangrijkste feedback voor beide studenten | H17: ...noteer hier de belangrijkste feedback voor beide studenten | K17: ...noteer hier de belangrijkste feedback voor beide studenten
B18: =Data!$B$6 -> Student 1 | C18: =IF(TAAL="Engels", Data!$E$26,Data!$E$25) -> Oordeel | D18: =Data!$B$6 -> Student 1 | E18: =IF(TAAL="Engels", Data!$E$26,Data!$E$25) -> Oordeel | F18: =Data!$B$6 -> Student 1 | G18: =IF(TAAL="Engels", Data!$E$26,Data!$E$25) -> Oordeel | H18: =Data!$B$6 -> Student 1 | I18: =IF(TAAL="Engels", Data!$E$26,Data!$E$25) -> Oordeel | K18: =Data!$B$6 -> Student 1 | L18: =IF(TAAL="Engels", Data!$E$26,Data!$E$25) -> Oordeel | M18: =IF(TAAL="Engels", Data!$E$26,Data!$E$25) -> Oordeel
B19: ...noteer hier de belangrijkste feedback voor de eerste student | D19: ...noteer hier de belangrijkste feedback voor de eerste student | F19: ...noteer hier de belangrijkste feedback voor de eerste student | H19: ...noteer hier de belangrijkste feedback voor de eerste student | K19: ...noteer hier de belangrijkste feedback voor de eerste student
B20: =Data!$B$8 -> Student 2 | C20: =IF(TAAL="Engels", Data!$E$26,Data!$E$25) -> Oordeel | D20: =Data!$B$8 -> Student 2 | E20: =IF(TAAL="Engels", Data!$E$26,Data!$E$25) -> Oordeel | F20: =Data!$B$8 -> Student 2 | G20: =IF(TAAL="Engels", Data!$E$26,Data!$E$25) -> Oordeel | H20: =Data!$B$8 -> Student 2 | I20: =IF(TAAL="Engels", Data!$E$26,Data!$E$25) -> Oordeel | K20: =Data!$B$8 -> Student 2 | L20: =IF(TAAL="Engels", Data!$E$26,Data!$E$25) -> Oordeel | M20: =IF(TAAL="Engels", Data!$E$26,Data!$E$25) -> Oordeel
B21: ...noteer hier de belangrijkste feedback voor de tweede student | D21: ...noteer hier de belangrijkste feedback voor de tweede student | F21: ...noteer hier de belangrijkste feedback voor de tweede student | H21: ...noteer hier de belangrijkste feedback voor de tweede student | K21: ...noteer hier de belangrijkste feedback voor de tweede student
A22: =IF(TAAL="Engels", Competenties!$D$4, Competenties!$A$4) -> Competentie 2: Probleem-oplossend vermogen, leveren van beroepsprestaties | B22: =IF(TAAL="Engels", Data!$E$24,Data!$E$23) -> Motivatie en toelichting | D22: =IF(TAAL="Engels", Data!$E$24,Data!$E$23) -> Motivatie en toelichting | F22: =IF(TAAL="Engels", Data!$E$24,Data!$E$23) -> Motivatie en toelichting | H22: =IF(TAAL="Engels", Data!$E$24,Data!$E$23) -> Motivatie en toelichting | K22: =IF(TAAL="Engels", Data!$E$24,Data!$E$23) -> Motivatie en toelichting
A23: =IF(TAAL="Engels", Competenties!$E$4, Competenties!$B$4) -> EISEN • Student formuleert vooraf heldere eisen aan de deliverables, welke aansluiten bij de behoeften van de opdrachtgever/klant UITVOEREN • Student realiseert de benodigde deliverables conform die eisen en verwachtingen • Student onderbouwt de keuzes gemaakt tijdens het realiseren van die deliverables • Student borgt de kwaliteit van de deliverables door passende tests, controles, validaties OVERDRACHT • Student zorgt er middels implementatie/overdrachts-activiteiten voor dat de opdrachtgever daadwerkelijk succes kan hebben met de geleverde resultaten • Student heeft een tevreden opdrachtgever MATE VAN ZELFSTANDIGHEID • Student(en) heeft/hebben hierin zelfstandig gewerkt. | B23: ...noteer hier de belangrijkste feedback voor beide studenten | D23: ...noteer hier de belangrijkste feedback voor beide studenten | F23: ...noteer hier de belangrijkste feedback voor beide studenten | H23: ...noteer hier de belangrijkste feedback voor beide studenten | K23: ...noteer hier de belangrijkste feedback voor beide studenten
B24: =Data!$B$6 -> Student 1 | C24: =IF(TAAL="Engels", Data!$E$26,Data!$E$25) -> Oordeel | D24: =Data!$B$6 -> Student 1 | E24: =IF(TAAL="Engels", Data!$E$26,Data!$E$25) -> Oordeel | F24: =Data!$B$6 -> Student 1 | G24: =IF(TAAL="Engels", Data!$E$26,Data!$E$25) -> Oordeel | H24: =Data!$B$6 -> Student 1 | I24: =IF(TAAL="Engels", Data!$E$26,Data!$E$25) -> Oordeel | K24: =Data!$B$6 -> Student 1 | L24: =IF(TAAL="Engels", Data!$E$26,Data!$E$25) -> Oordeel | M24: =IF(TAAL="Engels", Data!$E$26,Data!$E$25) -> Oordeel
B25: ...noteer hier de belangrijkste feedback de eerste student | D25: ...noteer hier de belangrijkste feedback de eerste student | F25: ...noteer hier de belangrijkste feedback de eerste student | H25: ...noteer hier de belangrijkste feedback de eerste student | K25: ...noteer hier de belangrijkste feedback de eerste student
B26: =Data!$B$8 -> Student 2 | C26: =IF(TAAL="Engels", Data!$E$26,Data!$E$25) -> Oordeel | D26: =Data!$B$8 -> Student 2 | E26: =IF(TAAL="Engels", Data!$E$26,Data!$E$25) -> Oordeel | F26: =Data!$B$8 -> Student 2 | G26: =IF(TAAL="Engels", Data!$E$26,Data!$E$25) -> Oordeel | H26: =Data!$B$8 -> Student 2 | I26: =IF(TAAL="Engels", Data!$E$26,Data!$E$25) -> Oordeel | K26: =Data!$B$8 -> Student 2 | L26: =IF(TAAL="Engels", Data!$E$26,Data!$E$25) -> Oordeel | M26: =IF(TAAL="Engels", Data!$E$26,Data!$E$25) -> Oordeel
B27: ...noteer hier de belangrijkste feedback voor de tweede student | D27: ...noteer hier de belangrijkste feedback voor de tweede student | F27: ...noteer hier de belangrijkste feedback voor de tweede student | H27: ...noteer hier de belangrijkste feedback voor de tweede student | K27: ...noteer hier de belangrijkste feedback voor de tweede student
A28: =IF(TAAL="Engels", Competenties!$D$5, Competenties!$A$5) -> Competentie 3: Onderzoekend vermogen | B28: =IF(TAAL="Engels", Data!$E$24,Data!$E$23) -> Motivatie en toelichting | D28: =IF(TAAL="Engels", Data!$E$24,Data!$E$23) -> Motivatie en toelichting | F28: =IF(TAAL="Engels", Data!$E$24,Data!$E$23) -> Motivatie en toelichting | H28: =IF(TAAL="Engels", Data!$E$24,Data!$E$23) -> Motivatie en toelichting | K28: =IF(TAAL="Engels", Data!$E$24,Data!$E$23) -> Motivatie en toelichting
A29: =IF(TAAL="Engels", Competenties!$E$5, Competenties!$B$5) -> ONDERZOEKEN • Student bepaalt een relevante hoofdvraag/probleemstelling • Student voert op systematische wijze onderzoek uit (denk aan: construeren logische set onderzoeksvragen, kiezen van passende onderzoeksmethoden, triangulatie, etc.) • Student verzamelt en analyseert ontbrekende informatie uit diverse bronnen KRITISCH DENKEN • Student gebruikt hierbij (wetenschappelijke) inzichten van anderen, oriënteert zich breed en is kritisch op gebruikte bronnen • Student overweegt alternatieven en onderbouwt keuzes door middel van onafhankelijke/objectieve informatie en logische redenering MATE VAN ZELFSTANDIGHEID • Student(en) heeft/hebben hierin zelfstandig gewerkt. | B29: ...noteer hier de belangrijkste feedback voor beide studenten | D29: ...noteer hier de belangrijkste feedback voor beide studenten | F29: ...noteer hier de belangrijkste feedback voor beide studenten | H29: ...noteer hier de belangrijkste feedback voor beide studenten | K29: ...noteer hier de belangrijkste feedback voor beide studenten
B30: =Data!$B$6 -> Student 1 | C30: =IF(TAAL="Engels", Data!$E$26,Data!$E$25) -> Oordeel | D30: =Data!$B$6 -> Student 1 | E30: =IF(TAAL="Engels", Data!$E$26,Data!$E$25) -> Oordeel | F30: =Data!$B$6 -> Student 1 | G30: =IF(TAAL="Engels", Data!$E$26,Data!$E$25) -> Oordeel | H30: =Data!$B$6 -> Student 1 | I30: =IF(TAAL="Engels", Data!$E$26,Data!$E$25) -> Oordeel | K30: =Data!$B$6 -> Student 1 | L30: =IF(TAAL="Engels", Data!$E$26,Data!$E$25) -> Oordeel | M30: =IF(TAAL="Engels", Data!$E$26,Data!$E$25) -> Oordeel
B31: ...noteer hier de belangrijkste feedback de eerste student | D31: ...noteer hier de belangrijkste feedback de eerste student | F31: ...noteer hier de belangrijkste feedback de eerste student | H31: ...noteer hier de belangrijkste feedback de eerste student | K31: ...noteer hier de belangrijkste feedback de eerste student
B32: =Data!$B$8 -> Student 2 | C32: =IF(TAAL="Engels", Data!$E$26,Data!$E$25) -> Oordeel | D32: =Data!$B$8 -> Student 2 | E32: =IF(TAAL="Engels", Data!$E$26,Data!$E$25) -> Oordeel | F32: =Data!$B$8 -> Student 2 | G32: =IF(TAAL="Engels", Data!$E$26,Data!$E$25) -> Oordeel | H32: =Data!$B$8 -> Student 2 | I32: =IF(TAAL="Engels", Data!$E$26,Data!$E$25) -> Oordeel | K32: =Data!$B$8 -> Student 2 | L32: =IF(TAAL="Engels", Data!$E$26,Data!$E$25) -> Oordeel | M32: =IF(TAAL="Engels", Data!$E$26,Data!$E$25) -> Oordeel
B33: ...noteer hier de belangrijkste feedback voor de tweede student | D33: ...noteer hier de belangrijkste feedback voor de tweede student | F33: ...noteer hier de belangrijkste feedback voor de tweede student | H33: ...noteer hier de belangrijkste feedback voor de tweede student | K33: ...noteer hier de belangrijkste feedback voor de tweede student
A34: =IF(TAAL="Engels", Competenties!$D$6, Competenties!$A$6) -> Competentie 4: Samenwerken & communiceren | B34: =IF(TAAL="Engels", Data!$E$24,Data!$E$23) -> Motivatie en toelichting | D34: =IF(TAAL="Engels", Data!$E$24,Data!$E$23) -> Motivatie en toelichting | F34: =IF(TAAL="Engels", Data!$E$24,Data!$E$23) -> Motivatie en toelichting | H34: =IF(TAAL="Engels", Data!$E$24,Data!$E$23) -> Motivatie en toelichting | K34: =IF(TAAL="Engels", Data!$E$24,Data!$E$23) -> Motivatie en toelichting
A35: =IF(TAAL="Engels", Competenties!$E$6, Competenties!$B$6) -> PROACTIEVE HOUDING • Student stemt proactief af met de relevante stakeholders, waaronder in elk geval de opdrachtgever, bedrijfsbegeleider en docent-begeleider. Daaronder valt in ieder geval het op de hoogte houden van de voortgang. MONDELING • Student laat goede mondelinge communicatievaardigheden zien, in bijvoorbeeld gesprekken en presentaties SCHRIFTELIJK • Student laat goede schriftelijke communicatievaardigheden zien (goed gestructureerd, taalgebruik is verzorgd, en voldoende passend bij de doelgroep) | B35: ...noteer hier de belangrijkste feedback voor beide studenten | D35: ...noteer hier de belangrijkste feedback voor beide studenten | F35: ...noteer hier de belangrijkste feedback voor beide studenten | H35: ...noteer hier de belangrijkste feedback voor beide studenten | K35: ...noteer hier de belangrijkste feedback voor beide studenten
B36: =Data!$B$6 -> Student 1 | C36: =IF(TAAL="Engels", Data!$E$26,Data!$E$25) -> Oordeel | D36: =Data!$B$6 -> Student 1 | E36: =IF(TAAL="Engels", Data!$E$26,Data!$E$25) -> Oordeel | F36: =Data!$B$6 -> Student 1 | G36: =IF(TAAL="Engels", Data!$E$26,Data!$E$25) -> Oordeel | H36: =Data!$B$6 -> Student 1 | I36: =IF(TAAL="Engels", Data!$E$26,Data!$E$25) -> Oordeel | K36: =Data!$B$6 -> Student 1 | L36: =IF(TAAL="Engels", Data!$E$26,Data!$E$25) -> Oordeel | M36: =IF(TAAL="Engels", Data!$E$26,Data!$E$25) -> Oordeel
B37: ...noteer hier de belangrijkste feedback de eerste student | D37: ...noteer hier de belangrijkste feedback de eerste student | F37: ...noteer hier de belangrijkste feedback de eerste student | H37: ...noteer hier de belangrijkste feedback de eerste student | K37: ...noteer hier de belangrijkste feedback de eerste student
B38: =Data!$B$8 -> Student 2 | C38: =IF(TAAL="Engels", Data!$E$26,Data!$E$25) -> Oordeel | D38: =Data!$B$8 -> Student 2 | E38: =IF(TAAL="Engels", Data!$E$26,Data!$E$25) -> Oordeel | F38: =Data!$B$8 -> Student 2 | G38: =IF(TAAL="Engels", Data!$E$26,Data!$E$25) -> Oordeel | H38: =Data!$B$8 -> Student 2 | I38: =IF(TAAL="Engels", Data!$E$26,Data!$E$25) -> Oordeel | K38: =Data!$B$8 -> Student 2 | L38: =IF(TAAL="Engels", Data!$E$26,Data!$E$25) -> Oordeel | M38: =IF(TAAL="Engels", Data!$E$26,Data!$E$25) -> Oordeel
B39: ...noteer hier de belangrijkste feedback voor de tweede student | D39: ...noteer hier de belangrijkste feedback voor de tweede student | F39: ...noteer hier de belangrijkste feedback voor de tweede student | H39: ...noteer hier de belangrijkste feedback voor de tweede student | K39: ...noteer hier de belangrijkste feedback voor de tweede student
A40: =IF(TAAL="Engels", Competenties!$D$7, Competenties!$A$7) -> Competentie 5: Professionele houding | B40: =IF(TAAL="Engels", Data!$E$24,Data!$E$23) -> Motivatie en toelichting | D40: =IF(TAAL="Engels", Data!$E$24,Data!$E$23) -> Motivatie en toelichting | F40: =IF(TAAL="Engels", Data!$E$24,Data!$E$23) -> Motivatie en toelichting | H40: =IF(TAAL="Engels", Data!$E$24,Data!$E$23) -> Motivatie en toelichting | K40: =IF(TAAL="Engels", Data!$E$24,Data!$E$23) -> Motivatie en toelichting
A41: =IF(TAAL="Engels", Competenties!$E$7, Competenties!$B$7) -> PROFESSIONEEL WERKNEMER/OPDRACHTNEMER • Student functioneert als beginnend professional in de organisatie • Student toont eigenaarschap voor de opdracht en neemt initiatief om de opdracht succesvol te voltooien MAATSCHAPPELIJKE VERANTWOORDELIJKHEID • Student houdt bij het uitvoeren van de opdracht expliciet rekening met de impact op anderen (denk aan: de maatschappij, milieu/planeet, privacy/security, etc.). ZELFSTURING • Student heeft inzicht in eigen competenties en handelen (zelfreflectie) • Student toont eigenaarschap van de persoonlijke ontwikkeling door onderbouwde keuzes te maken • Student gaat professioneel en effectief om met (on)gevraagde feedback | B41: ...noteer hier de belangrijkste feedback voor beide studenten | D41: ...noteer hier de belangrijkste feedback voor beide studenten | F41: ...noteer hier de belangrijkste feedback voor beide studenten | H41: ...noteer hier de belangrijkste feedback voor beide studenten | K41: ...noteer hier de belangrijkste feedback voor beide studenten
...

Sheet Feedback docent
A1: Feedback tijdens fasegesprekken | B1: invulinstructie: vul de witte cellen in, maak waar van toepassing onderscheid tussen de studenten (gebruik ALT+Enter voor nieuwe tekstregel binnen de cel)
A2: =Data!B3 -> 0 | B2: =Data!B5 -> najaar 2024
A3: Student 1 (naam & studentnummer) | B3: =Data!B6 -> Student 1 | C3: =Data!B7 -> nummer 1
A4: Student 2 (naam & studentnummer) | B4: =Data!B8 -> Student 2 | C4: =Data!B9 -> nummer 2
A5: Titel opdracht | B5: =Data!B12 -> opdr titel
A6: Naam bedrijfsbegeleider | B6: =Data!B11 -> begeleider bedrijf
A7: Naam docent-begeleider | B7: =Data!B13 -> docent 1
A8: Naam 2de docent (voorzitter) | B8: =Data!B14 -> docent 2
A9: Naam extern gecommitteerde | B9: =Data!B15 -> externe
B10: FASE 1 | D10: FASE 2 | F10: FASE 3 | H10: =IF(TAAL="Engels", Data!$E$38,Data!$E$37) -> Afstudeertraject | J10: =IF(TAAL="Engels", Data!$E$36,Data!$E$35) -> Adviesbeoordeling Bedrijfsbegeleider | M10: FASE 5/6 | O10: HERKANSING
A11: Datum (van invullen)
A12: VOORAF | B12: =IF(TAAL="Engels", Data!$E$32,Data!$E$31) -> Opgeleverde producten | D12: =IF(TAAL="Engels", Data!$E$32,Data!$E$31) -> Opgeleverde producten | F12: =IF(TAAL="Engels", Data!$E$32,Data!$E$31) -> Opgeleverde producten | H12: =IF(TAAL="Engels", Data!$E$32,Data!$E$31) -> Opgeleverde producten | J12: =IF(TAAL="Engels", Data!$E$32,Data!$E$31) -> Opgeleverde producten | M12: =IF(TAAL="Engels", Data!$E$32,Data!$E$31) -> Opgeleverde producten | O12: Voer hier de voorlopige beoordeling in ter voorbereiding op de herkansingszitting.
B14: =IF(TAAL="Engels", Data!$E$34,Data!$E$33) -> Bijzondere omstandigheden | D14: =IF(TAAL="Engels", Data!$E$34,Data!$E$33) -> Bijzondere omstandigheden | F14: =IF(TAAL="Engels", Data!$E$34,Data!$E$33) -> Bijzondere omstandigheden | H14: =IF(TAAL="Engels", Data!$E$34,Data!$E$33) -> Bijzondere omstandigheden | J14: =IF(TAAL="Engels", Data!$E$34,Data!$E$33) -> Bijzondere omstandigheden | M14: =IF(TAAL="Engels", Data!$E$34,Data!$E$33) -> Bijzondere omstandigheden
K15: Voer hier de voorlopige cijferbeoordeling in ter voorbereiding op de zitting.
A16: =IF(TAAL="Engels", Competenties!$D$3, Competenties!$A$3) -> Competentie 1: Planmatig werken | B16: =IF(TAAL="Engels", Data!$E$24,Data!$E$23) -> Motivatie en toelichting | D16: =IF(TAAL="Engels", Data!$E$24,Data!$E$23) -> Motivatie en toelichting | F16: =IF(TAAL="Engels", Data!$E$24,Data!$E$23) -> Motivatie en toelichting | H16: =IF(TAAL="Engels", Data!$E$24,Data!$E$23) -> Motivatie en toelichting | J16: =IF(TAAL="Engels", Data!$E$24,Data!$E$23) -> Motivatie en toelichting | M16: =IF(TAAL="Engels", Data!$E$24,Data!$E$23) -> Motivatie en toelichting
A17: =IF(TAAL="Engels", Competenties!$E$3, Competenties!$B$3) -> WAT & WAAROM • Student geeft de context van de opdracht aan, waarbij probleem en/of aanleiding, doel, stakeholders en scope duidelijk worden • Student beschrijft de beoogde deliverables (producten, handelingen) van de opdracht • Student neemt hierbij (zoals stakeholders, deliverables) zowel school als bedrijf mee, in de juiste balans. HOE • Student bepaalt fasen en activiteiten bij de opdracht, verwerkt deze in een realistische planning, en bepaalt relevante risico’s en bijpassende maatregelen • Student onderbouwt de gekozen aanpak (methoden & technieken), welke past bij doel en context van de opdracht • Student werkt volgens het PvA en wijkt hier in overleg vanaf waar nodig. MATE VAN ZELFSTANDIGHEID • Student(en) komt/komen zelfstandig tot een bruikbaar (samenhangend, volledig en van voldoende kwaliteit) Plan van Aanpak. | B17: ...noteer hier de belangrijkste feedback voor beide studenten | D17: ...noteer hier de belangrijkste feedback voor beide studenten | F17: ...noteer hier de belangrijkste feedback voor beide studenten | H17: ...noteer hier de belangrijkste feedback voor beide studenten | J17: ...noteer hier de belangrijkste feedback voor beide studenten | M17: ...noteer hier de belangrijkste feedback voor beide studenten
B18: =Data!$B$6 -> Student 1 | C18: =IF(TAAL="Engels", Data!$E$26,Data!$E$25) -> Oordeel | D18: =Data!$B$6 -> Student 1 | E18: =IF(TAAL="Engels", Data!$E$26,Data!$E$25) -> Oordeel | F18: =Data!$B$6 -> Student 1 | G18: =IF(TAAL="Engels", Data!$E$26,Data!$E$25) -> Oordeel | H18: =Data!$B$6 -> Student 1 | J18: =Data!$B$6 -> Student 1 | K18: =IF(TAAL="Engels", Data!$E$26,Data!$E$25) -> Oordeel | M18: =Data!$B$6 -> Student 1 | N18: =IF(TAAL="Engels", Data!$E$26,Data!$E$25) -> Oordeel | O18: =IF(TAAL="Engels", Data!$E$26,Data!$E$25) -> Oordeel
B19: ...noteer hier de belangrijkste feedback voor de eerste student | D19: ...noteer hier de belangrijkste feedback voor de eerste student | F19: ...noteer hier de belangrijkste feedback voor de eerste student | H19: ...noteer hier de belangrijkste feedback voor de eerste student | J19: ...noteer hier de belangrijkste feedback voor de eerste student | M19: ...noteer hier de belangrijkste feedback voor de eerste student
B20: =Data!$B$8 -> Student 2 | C20: =IF(TAAL="Engels", Data!$E$26,Data!$E$25) -> Oordeel | D20: =Data!$B$8 -> Student 2 | E20: =IF(TAAL="Engels", Data!$E$26,Data!$E$25) -> Oordeel | F20: =Data!$B$8 -> Student 2 | G20: =IF(TAAL="Engels", Data!$E$26,Data!$E$25) -> Oordeel | H20: =Data!$B$8 -> Student 2 | J20: =Data!$B$8 -> Student 2 | K20: =IF(TAAL="Engels", Data!$E$26,Data!$E$25) -> Oordeel | M20: =Data!$B$8 -> Student 2 | N20: =IF(TAAL="Engels", Data!$E$26,Data!$E$25) -> Oordeel | O20: =IF(TAAL="Engels", Data!$E$26,Data!$E$25) -> Oordeel
B21: ...noteer hier de belangrijkste feedback voor de tweede student | D21: ...noteer hier de belangrijkste feedback voor de tweede student | F21: ...noteer hier de belangrijkste feedback voor de tweede student | H21: ...noteer hier de belangrijkste feedback voor de tweede student | J21: ...noteer hier de belangrijkste feedback voor de tweede student | M21: ...noteer hier de belangrijkste feedback voor de tweede student
A22: =IF(TAAL="Engels", Competenties!$D$4, Competenties!$A$4) -> Competentie 2: Probleem-oplossend vermogen, leveren van beroepsprestaties | B22: =IF(TAAL="Engels", Data!$E$24,Data!$E$23) -> Motivatie en toelichting | D22: =IF(TAAL="Engels", Data!$E$24,Data!$E$23) -> Motivatie en toelichting | F22: =IF(TAAL="Engels", Data!$E$24,Data!$E$23) -> Motivatie en toelichting | H22: =IF(TAAL="Engels", Data!$E$24,Data!$E$23) -> Motivatie en toelichting | J22: =IF(TAAL="Engels", Data!$E$24,Data!$E$23) -> Motivatie en toelichting | M22: =IF(TAAL="Engels", Data!$E$24,Data!$E$23) -> Motivatie en toelichting
A23: =IF(TAAL="Engels", Competenties!$E$4, Competenties!$B$4) -> EISEN • Student formuleert vooraf heldere eisen aan de deliverables, welke aansluiten bij de behoeften van de opdrachtgever/klant UITVOEREN • Student realiseert de benodigde deliverables conform die eisen en verwachtingen • Student onderbouwt de keuzes gemaakt tijdens het realiseren van die deliverables • Student borgt de kwaliteit van de deliverables door passende tests, controles, validaties OVERDRACHT • Student zorgt er middels implementatie/overdrachts-activiteiten voor dat de opdrachtgever daadwerkelijk succes kan hebben met de geleverde resultaten • Student heeft een tevreden opdrachtgever MATE VAN ZELFSTANDIGHEID • Student(en) heeft/hebben hierin zelfstandig gewerkt. | B23: ...noteer hier de belangrijkste feedback voor beide studenten | D23: ...noteer hier de belangrijkste feedback voor beide studenten | F23: ...noteer hier de belangrijkste feedback voor beide studenten | H23: ...noteer hier de belangrijkste feedback voor beide studenten | J23: ...noteer hier de belangrijkste feedback voor beide studenten | M23: ...noteer hier de belangrijkste feedback voor beide studenten
B24: =Data!$B$6 -> Student 1 | C24: =IF(TAAL="Engels", Data!$E$26,Data!$E$25) -> Oordeel | D24: =Data!$B$6 -> Student 1 | E24: =IF(TAAL="Engels", Data!$E$26,Data!$E$25) -> Oordeel | F24: =Data!$B$6 -> Student 1 | G24: =IF(TAAL="Engels", Data!$E$26,Data!$E$25) -> Oordeel | H24: =Data!$B$6 -> Student 1 | J24: =Data!$B$6 -> Student 1 | K24: =IF(TAAL="Engels", Data!$E$26,Data!$E$25) -> Oordeel | M24: =Data!$B$6 -> Student 1 | N24: =IF(TAAL="Engels", Data!$E$26,Data!$E$25) -> Oordeel | O24: =IF(TAAL="Engels", Data!$E$26,Data!$E$25) -> Oordeel
B25: ...noteer hier de belangrijkste feedback de eerste student | D25: ...noteer hier de belangrijkste feedback de eerste student | F25: ...noteer hier de belangrijkste feedback de eerste student | H25: ...noteer hier de belangrijkste feedback de eerste student | J25: ...noteer hier de belangrijkste feedback de eerste student | M25: ...noteer hier de belangrijkste feedback de eerste student
B26: =Data!$B$8 -> Student 2 | C26: =IF(TAAL="Engels", Data!$E$26,Data!$E$25) -> Oordeel | D26: =Data!$B$8 -> Student 2 | E26: =IF(TAAL="Engels", Data!$E$26,Data!$E$25) -> Oordeel | F26: =Data!$B$8 -> Student 2 | G26: =IF(TAAL="Engels", Data!$E$26,Data!$E$25) -> Oordeel | H26: =Data!$B$8 -> Student 2 | J26: =Data!$B$8 -> Student 2 | K26: =IF(TAAL="Engels", Data!$E$26,Data!$E$25) -> Oordeel | M26: =Data!$B$8 -> Student 2 | N26: =IF(TAAL="Engels", Data!$E$26,Data!$E$25) -> Oordeel | O26: =IF(TAAL="Engels", Data!$E$26,Data!$E$25) -> Oordeel
B27: ...noteer hier de belangrijkste feedback voor de tweede student | D27: ...noteer hier de belangrijkste feedback voor de tweede student | F27: ...noteer hier de belangrijkste feedback voor de tweede student | H27: ...noteer hier de belangrijkste feedback voor de tweede student | J27: ...noteer hier de belangrijkste feedback voor de tweede student | M27: ...noteer hier de belangrijkste feedback voor de tweede student
A28: =IF(TAAL="Engels", Competenties!$D$5, Competenties!$A$5) -> Competentie 3: Onderzoekend vermogen | B28: =IF(TAAL="Engels", Data!$E$24,Data!$E$23) -> Motivatie en toelichting | D28: =IF(TAAL="Engels", Data!$E$24,Data!$E$23) -> Motivatie en toelichting | F28: =IF(TAAL="Engels", Data!$E$24,Data!$E$23) -> Motivatie en toelichting | H28: =IF(TAAL="Engels", Data!$E$24,Data!$E$23) -> Motivatie en toelichting | J28: =IF(TAAL="Engels", Data!$E$24,Data!$E$23) -> Motivatie en toelichting | M28: =IF(TAAL="Engels", Data!$E$24,Data!$E$23) -> Motivatie en toelichting
A29: =IF(TAAL="Engels", Competenties!$E$5, Competenties!$B$5) -> ONDERZOEKEN • Student bepaalt een relevante hoofdvraag/probleemstelling • Student voert op systematische wijze onderzoek uit (denk aan: construeren logische set onderzoeksvragen, kiezen van passende onderzoeksmethoden, triangulatie, etc.) • Student verzamelt en analyseert ontbrekende informatie uit diverse bronnen KRITISCH DENKEN • Student gebruikt hierbij (wetenschappelijke) inzichten van anderen, oriënteert zich breed en is kritisch op gebruikte bronnen • Student overweegt alternatieven en onderbouwt keuzes door middel van onafhankelijke/objectieve informatie en logische redenering MATE VAN ZELFSTANDIGHEID • Student(en) heeft/hebben hierin zelfstandig gewerkt. | B29: ...noteer hier de belangrijkste feedback voor beide studenten | D29: ...noteer hier de belangrijkste feedback voor beide studenten | F29: ...noteer hier de belangrijkste feedback voor beide studenten | H29: ...noteer hier de belangrijkste feedback voor beide studenten | J29: ...noteer hier de belangrijkste feedback voor beide studenten | M29: ...noteer hier de belangrijkste feedback voor beide studenten
B30: =Data!$B$6 -> Student 1 | C30: =IF(TAAL="Engels", Data!$E$26,Data!$E$25) -> Oordeel | D30: =Data!$B$6 -> Student 1 | E30: =IF(TAAL="Engels", Data!$E$26,Data!$E$25) -> Oordeel | F30: =Data!$B$6 -> Student 1 | G30: =IF(TAAL="Engels", Data!$E$26,Data!$E$25) -> Oordeel | H30: =Data!$B$6 -> Student 1 | J30: =Data!$B$6 -> Student 1 | K30: =IF(TAAL="Engels", Data!$E$26,Data!$E$25) -> Oordeel | M30: =Data!$B$6 -> Student 1 | N30: =IF(TAAL="Engels", Data!$E$26,Data!$E$25) -> Oordeel | O30: =IF(TAAL="Engels", Data!$E$26,Data!$E$25) -> Oordeel
B31: ...noteer hier de belangrijkste feedback de eerste student | D31: ...noteer hier de belangrijkste feedback de eerste student | F31: ...noteer hier de belangrijkste feedback de eerste student | H31: ...noteer hier de belangrijkste feedback de eerste student | J31: ...noteer hier de belangrijkste feedback de eerste student | M31: ...noteer hier de belangrijkste feedback de eerste student
B32: =Data!$B$8 -> Student 2 | C32: =IF(TAAL="Engels", Data!$E$26,Data!$E$25) -> Oordeel | D32: =Data!$B$8 -> Student 2 | E32: =IF(TAAL="Engels", Data!$E$26,Data!$E$25) -> Oordeel | F32: =Data!$B$8 -> Student 2 | G32: =IF(TAAL="Engels", Data!$E$26,Data!$E$25) -> Oordeel | H32: =Data!$B$8 -> Student 2 | J32: =Data!$B$8 -> Student 2 | K32: =IF(TAAL="Engels", Data!$E$26,Data!$E$25) -> Oordeel | M32: =Data!$B$8 -> Student 2 | N32: =IF(TAAL="Engels", Data!$E$26,Data!$E$25) -> Oordeel | O32: =IF(TAAL="Engels", Data!$E$26,Data!$E$25) -> Oordeel
B33: ...noteer hier de belangrijkste feedback voor de tweede student | D33: ...noteer hier de belangrijkste feedback voor de tweede student | F33: ...noteer hier de belangrijkste feedback voor de tweede student | H33: ...noteer hier de belangrijkste feedback voor de tweede student | J33: ...noteer hier de belangrijkste feedback voor de tweede student | M33: ...noteer hier de belangrijkste feedback voor de tweede student
A34: =IF(TAAL="Engels", Competenties!$D$6, Competenties!$A$6) -> Competentie 4: Samenwerken & communiceren | B34: =IF(TAAL="Engels", Data!$E$24,Data!$E$23) -> Motivatie en toelichting | D34: =IF(TAAL="Engels", Data!$E$24,Data!$E$23) -> Motivatie en toelichting | F34: =IF(TAAL="Engels", Data!$E$24,Data!$E$23) -> Motivatie en toelichting | H34: =IF(TAAL="Engels", Data!$E$24,Data!$E$23) -> Motivatie en toelichting | J34: =IF(TAAL="Engels", Data!$E$24,Data!$E$23) -> Motivatie en toelichting | M34: =IF(TAAL="Engels", Data!$E$24,Data!$E$23) -> Motivatie en toelichting
A35: =IF(TAAL="Engels", Competenties!$E$6, Competenties!$B$6) -> PROACTIEVE HOUDING • Student stemt proactief af met de relevante stakeholders, waaronder in elk geval de opdrachtgever, bedrijfsbegeleider en docent-begeleider. Daaronder valt in ieder geval het op de hoogte houden van de voortgang. MONDELING • Student laat goede mondelinge communicatievaardigheden zien, in bijvoorbeeld gesprekken en presentaties SCHRIFTELIJK • Student laat goede schriftelijke communicatievaardigheden zien (goed gestructureerd, taalgebruik is verzorgd, en voldoende passend bij de doelgroep) | B35: ...noteer hier de belangrijkste feedback voor beide studenten | D35: ...noteer hier de belangrijkste feedback voor beide studenten | F35: ...noteer hier de belangrijkste feedback voor beide studenten | H35: ...noteer hier de belangrijkste feedback voor beide studenten | J35: ...noteer hier de belangrijkste feedback voor beide studenten | M35: ...noteer hier de belangrijkste feedback voor beide studenten
B36: =Data!$B$6 -> Student 1 | C36: =IF(TAAL="Engels", Data!$E$26,Data!$E$25) -> Oordeel | D36: =Data!$B$6 -> Student 1 | E36: =IF(TAAL="Engels", Data!$E$26,Data!$E$25) -> Oordeel | F36: =Data!$B$6 -> Student 1 | G36: =IF(TAAL="Engels", Data!$E$26,Data!$E$25) -> Oordeel | H36: =Data!$B$6 -> Student 1 | J36: =Data!$B$6 -> Student 1 | K36: =IF(TAAL="Engels", Data!$E$26,Data!$E$25) -> Oordeel | M36: =Data!$B$6 -> Student 1 | N36: =IF(TAAL="Engels", Data!$E$26,Data!$E$25) -> Oordeel | O36: =IF(TAAL="Engels", Data!$E$26,Data!$E$25) -> Oordeel
B37: ...noteer hier de belangrijkste feedback de eerste student | D37: ...noteer hier de belangrijkste feedback de eerste student | F37: ...noteer hier de belangrijkste feedback de eerste student | H37: ...noteer hier de belangrijkste feedback de eerste student | J37: ...noteer hier de belangrijkste feedback de eerste student | M37: ...noteer hier de belangrijkste feedback de eerste student
B38: =Data!$B$8 -> Student 2 | C38: =IF(TAAL="Engels", Data!$E$26,Data!$E$25) -> Oordeel | D38: =Data!$B$8 -> Student 2 | E38: =IF(TAAL="Engels", Data!$E$26,Data!$E$25) -> Oordeel | F38: =Data!$B$8 -> Student 2 | G38: =IF(TAAL="Engels", Data!$E$26,Data!$E$25) -> Oordeel | H38: =Data!$B$8 -> Student 2 | J38: =Data!$B$8 -> Student 2 | K38: =IF(TAAL="Engels", Data!$E$26,Data!$E$25) -> Oordeel | M38: =Data!$B$8 -> Student 2 | N38: =IF(TAAL="Engels", Data!$E$26,Data!$E$25) -> Oordeel | O38: =IF(TAAL="Engels", Data!$E$26,Data!$E$25) -> Oordeel
B39: ...noteer hier de belangrijkste feedback voor de tweede student | D39: ...noteer hier de belangrijkste feedback voor de tweede student | F39: ...noteer hier de belangrijkste feedback voor de tweede student | H39: ...noteer hier de belangrijkste feedback voor de tweede student | J39: ...noteer hier de belangrijkste feedback voor de tweede student | M39: ...noteer hier de belangrijkste feedback voor de tweede student
A40: =IF(TAAL="Engels", Competenties!$D$7, Competenties!$A$7) -> Competentie 5: Professionele houding | B40: =IF(TAAL="Engels", Data!$E$24,Data!$E$23) -> Motivatie en toelichting | D40: =IF(TAAL="Engels", Data!$E$24,Data!$E$23) -> Motivatie en toelichting | F40: =IF(TAAL="Engels", Data!$E$24,Data!$E$23) -> Motivatie en toelichting | H40: =IF(TAAL="Engels", Data!$E$24,Data!$E$23) -> Motivatie en toelichting | J40: =IF(TAAL="Engels", Data!$E$24,Data!$E$23) -> Motivatie en toelichting | M40: =IF(TAAL="Engels", Data!$E$24,Data!$E$23) -> Motivatie en toelichting
A41: =IF(TAAL="Engels", Competenties!$E$7, Competenties!$B$7) -> PROFESSIONEEL WERKNEMER/OPDRACHTNEMER • Student functioneert als beginnend professional in de organisatie • Student toont eigenaarschap voor de opdracht en neemt initiatief om de opdracht succesvol te voltooien MAATSCHAPPELIJKE VERANTWOORDELIJKHEID • Student houdt bij het uitvoeren van de opdracht expliciet rekening met de impact op anderen (denk aan: de maatschappij, milieu/planeet, privacy/security, etc.). ZELFSTURING • Student heeft inzicht in eigen competenties en handelen (zelfreflectie) • Student toont eigenaarschap van de persoonlijke ontwikkeling door onderbouwde keuzes te maken • Student gaat professioneel en effectief om met (on)gevraagde feedback | B41: ...noteer hier de belangrijkste feedback voor beide studenten | D41: ...noteer hier de belangrijkste feedback voor beide studenten | F41: ...noteer hier de belangrijkste feedback voor beide studenten | H41: ...noteer hier de belangrijkste feedback voor beide studenten | J41: ...noteer hier de belangrijkste feedback voor beide studenten | M41: ...noteer hier de belangrijkste feedback voor beide studenten
...

Sheet Afstuderen Eind
A1: Eindbeoordeling Afstudeerzitting | E1: invulinstructie: vul de witte cellen in | G1: Eindbeoordeling Afstudeerzitting | K1: invulinstructie: vul de witte cellen in
A2: =Data!B3 -> 0 | B2: =Data!B5 -> najaar 2024 | G2: =Data!B3 -> 0 | H2: =Data!B5 -> najaar 2024
A3: Student 1 (naam & studentnummer) | B3: =Data!B6 -> Student 1 | E3: =Data!B7 -> nummer 1 | G3: Student 2 (naam & studentnummer) | H3: =Data!B8 -> Student 2 | K3: =Data!B9 -> nummer 2
A4: Titel opdracht | B4: =Data!B12 -> opdr titel | G4: Titel opdracht | H4: =Data!B12 -> opdr titel
A5: Naam bedrijfsbegeleider | B5: =Data!B11 -> begeleider bedrijf | G5: Naam bedrijfsbegeleider | H5: =Data!B11 -> begeleider bedrijf
A6: Naam docent-begeleider | B6: =Data!B13 -> docent 1 | G6: Naam docent-begeleider | H6: =Data!B13 -> docent 1
A7: Naam 2de docent (voorzitter) | B7: =Data!B14 -> docent 2 | G7: Naam 2de docent (voorzitter) | H7: =Data!B14 -> docent 2
A8: Naam extern gecommitteerde | B8: =Data!B15 -> externe | G8: Naam extern gecommitteerde | H8: =Data!B15 -> externe
A9: Datum | G9: Datum
A10: =IF(TAAL="Engels", Data!$E$34,Data!$E$33) -> Bijzondere omstandigheden | G10: =IF(TAAL="Engels", Data!$E$34,Data!$E$33) -> Bijzondere omstandigheden
A11: Spelen/speelden er bijzondere omstandigheden, waarmee rekening gehouden dient te worden tijdens de afstudeerzitting of de beoordeling? | G11: =A11 -> Spelen/speelden er bijzondere omstandigheden, waarmee rekening gehouden dient te worden tijdens de afstudeerzitting of de beoordeling?
A13: Verdediging | G13: Verdediging
A14: Feedback op verdediging. Denk aan zelfverzekerheid, kwaliteit van de antwoorden, aansluiten bij je publiek. | G14: Feedback op verdediging. Denk aan zelfverzekerheid, kwaliteit van de antwoorden, aansluiten bij je publiek.
A16: Beoordeling | G16: Beoordeling
A17: Competenties Alle compenties dienen voldoende te zijn om te kunnen slagen. Indien er één of meerdere competenties onvoldoende zijn, dan vul je bij de 'Totaal beoordeling' een 5,0 in. | C17: Advies bedrijfs-begeleider | D17: Voorlopige beoordeling docent | E17: Eindoordeel (default Eind Docent in wit, pas waar nodig aan o.b.v. zitting) | G17: Competenties Alle compenties dienen voldoende te zijn om te kunnen slagen. Indien er één of meerdere competenties onvoldoende zijn, dan vul je bij de 'Totaal beoordeling' een 5,0 in. | I17: Advies bedrijfs-begeleider | J17: Voorlopige beoordeling docent | K17: Eindoordeel (default Eind Docent in wit, pas waar nodig aan o.b.v. zitting)
A18: =IF(TAAL="Engels", Competenties!$D$3, Competenties!$A$3) -> Competentie 1: Planmatig werken | C18: ='Feedback bedrijfsbegeleider'!I19 -> 0 | D18: ='Feedback docent'!K19 -> 0 | E18: =D18 -> 0 | G18: =IF(TAAL="Engels", Competenties!$D$3, Competenties!$A$3) -> Competentie 1: Planmatig werken | I18: ='Feedback bedrijfsbegeleider'!I21 -> 0 | J18: ='Feedback docent'!K21 -> 0 | K18: =J18 -> 0
A19: =IF(TAAL="Engels", Competenties!$D$4, Competenties!$A$4) -> Competentie 2: Probleem-oplossend vermogen, leveren van beroepsprestaties | C19: ='Feedback bedrijfsbegeleider'!I25 -> 0 | D19: ='Feedback docent'!K25 -> 0 | E19: =D19 -> 0 | G19: =IF(TAAL="Engels", Competenties!$D$4, Competenties!$A$4) -> Competentie 2: Probleem-oplossend vermogen, leveren van beroepsprestaties | I19: ='Feedback bedrijfsbegeleider'!I27 -> 0 | J19: ='Feedback docent'!K27 -> 0 | K19: =J19 -> 0
A20: =IF(TAAL="Engels", Competenties!$D$5, Competenties!$A$5) -> Competentie 3: Onderzoekend vermogen | C20: ='Feedback bedrijfsbegeleider'!I31 -> 0 | D20: ='Feedback docent'!K31 -> 0 | E20: =D20 -> 0 | G20: =IF(TAAL="Engels", Competenties!$D$5, Competenties!$A$5) -> Competentie 3: Onderzoekend vermogen | I20: ='Feedback bedrijfsbegeleider'!I33 -> 0 | J20: ='Feedback docent'!K33 -> 0 | K20: =J20 -> 0
A21: =IF(TAAL="Engels", Competenties!$D$6, Competenties!$A$6) -> Competentie 4: Samenwerken & communiceren | C21: ='Feedback bedrijfsbegeleider'!I37 -> 0 | D21: ='Feedback docent'!K37 -> 0 | E21: =D21 -> 0 | G21: =IF(TAAL="Engels", Competenties!$D$6, Competenties!$A$6) -> Competentie 4: Samenwerken & communiceren | I21: ='Feedback bedrijfsbegeleider'!I39 -> 0 | J21: ='Feedback docent'!K39 -> 0 | K21: =J21 -> 0
A22: =IF(TAAL="Engels", Competenties!$D$7, Competenties!$A$7) -> Competentie 5: Professionele houding | C22: ='Feedback bedrijfsbegeleider'!I43 -> 0 | D22: ='Feedback docent'!K43 -> 0 | E22: =D22 -> 0 | G22: =IF(TAAL="Engels", Competenties!$D$7, Competenties!$A$7) -> Competentie 5: Professionele houding | I22: ='Feedback bedrijfsbegeleider'!I45 -> 0 | J22: ='Feedback docent'!K45 -> 0 | K22: =J22 -> 0
A23: Verdediging tijdens zitting | G23: =A23 -> Verdediging tijdens zitting
A24: Totaal beoordeling (competentie 2 telt dubbel mee. Eindcijfer afronden op halve cijfer) | E24: =ROUND(((SUM(E18:E23)+E19)/7)*2,0)/2 -> 0 | G24: Totaal beoordeling (competentie 2 telt dubbel mee. Eindcijfer afronden op halve cijfer) | K24: =ROUND(((SUM(K18:K23)+K19)/7)*2,0)/2 -> 0
A25: Motivatie en toelichting | G25: Motivatie en toelichting
A26: Verplicht indien eindoordeel van een of meer onderdelen afwijkt van voorlopige beoordeling docent-begeleider, n.a.v. voorbespreking en/of presentatie&verdediging door de student. Ook kunnen hier de belangrijkste commentaren van de 2de lezer en de extern gecommitteerde genoteerd worden. | G26: =A26 -> Verplicht indien eindoordeel van een of meer onderdelen afwijkt van voorlopige beoordeling docent-begeleider, n.a.v. voorbespreking en/of presentatie&verdediging door de student. Ook kunnen hier de belangrijkste commentaren van de 2de lezer en de extern gecommitteerde genoteerd worden.
A28: Gemaakte afspraken | G28: Gemaakte afspraken
A29: Verplicht indien eindoordeel onvoldoende. | G29: =A29 -> Verplicht indien eindoordeel onvoldoende.
A31: Ondertekening | G31: Ondertekening
A32: Student tekent voor gezien. | G32: Student tekent voor gezien.
A33: =Data!B14 -> docent 2 | B33: =Data!B11 -> begeleider bedrijf | G33: =Data!B14 -> docent 2 | H33: =Data!B11 -> begeleider bedrijf
A34: =Data!B15 -> externe | B34: =Data!B6 -> Student 1 | G34: =Data!B15 -> externe | H34: =Data!B8 -> Student 2
A35: =Data!B13 -> docent 1 | G35: =Data!B13 -> docent 1
